<?xml version="1.0" ?>
<!-- URDF of the KUKA iiwa 14 robot generated by robcogen and extended manually -->
<!-- Added interias and other properties by hand.                               -->
<robot name="KUKAiiwa14">

  <link name="iiwaBase">
    <inertial>
      <origin xyz="0.00000 0.00000 0.00000"/>
      <mass value="8.00000"/>
      <inertia ixx="0.00095" iyy="0.00133" izz="0.00118" ixy="0.00000" ixz="-0.00000" iyz="-0.00006"/>
    </inertial>
    <visual>
      <origin xyz="0.0 0.0 0.0" rpy="0.0 0.0 0.0" />            
      <geometry>
        <mesh filename="package://robot_properties_iiwa/meshes/iiwa14_base.stl" scale="0.001 0.001 0.001" />
      </geometry>
    </visual>    
  </link>


  <joint name="A1" type="revolute">
    <origin xyz="0.00000 0.00000 0.15750" rpy="0.0 0.0 0.0"/>
    <parent link="iiwaBase"/>
    <child  link="L1"/>
    <limit effort="30" velocity="1.0"/>
    <axis xyz="0 0 1"/>
  </joint>


  <link name="L1">
    <inertial>
      <origin xyz="0.00000 0.00000 0.00000"/>
      <mass value="4.00000"/>
      <inertia ixx="0.00095" iyy="0.00133" izz="0.00118" ixy="0.00000" ixz="-0.00000" iyz="-0.00006"/>
    </inertial>
    <visual>
      <origin xyz="0.0 0.0 0.0" rpy="0.0 0.0 0.0"/>
      <geometry>
	      <mesh filename="package://robot_properties_iiwa/meshes/iiwa14_link1.stl" scale="0.001 0.001 0.001" />
      </geometry>
    </visual>
  </link>  


  <joint name="A2" type="revolute">
    <origin xyz="0.00000 0.00000 0.20250" rpy="2.3561944901923457 -1.5707962635746238 2.3561944901923457"/>
    <parent link="L1"/>
    <child  link="L2"/>
    <limit effort="30" velocity="1.0"/>
    <axis xyz="0 0 1"/>
  </joint>


  <link name="L2">
    <inertial>
      <origin xyz="0.20920 -0.00010 0.04730"/>
      <mass value="4.00000"/>
      <inertia ixx="0.00145" iyy="0.00986" izz="0.00951" ixy="-0.00000" ixz="0.00096" iyz="-0.00000"/>
    </inertial>
    <visual>
      <origin xyz="0.0 0.0 0.0" rpy="0.0 0.0 0.0"/>
      <geometry>
	      <mesh filename="package://robot_properties_iiwa/meshes/iiwa14_link2.stl" scale="0.001 0.001 0.001" />
      </geometry>
    </visual>
  </link>


  <joint name="A3" type="revolute">
    <origin xyz="0.20450 0.00000 0.00000" rpy="1.5707963267948948 -4.371139000186238E-8 1.5707963705062866"/>
    <parent link="L2"/>
    <child  link="L3"/>
    <limit effort="30" velocity="1.0"/>
    <axis xyz="0 0 1"/>
  </joint>


  <link name="L3">
    <inertial>
      <origin xyz="0.20920 0.00010 -0.04730"/>
      <mass value="4.00000"/>
      <inertia ixx="0.00145" iyy="0.00986" izz="0.00951" ixy="-0.00000" ixz="-0.00096" iyz="0.00000"/>
    </inertial> 
    <visual>
      <origin xyz="0.0 0.0 0.0" rpy="0.0 0.0 0.0"/>
      <geometry>
	      <mesh filename="package://robot_properties_iiwa/meshes/iiwa14_link3.stl" scale="0.001 0.001 0.001" />
      </geometry>
    </visual>  
  </link>


  <joint name="A4" type="revolute">
    <origin xyz="0.00000 0.00000 0.21550" rpy="1.5707963705062866 -0.0 0.0"/>
    <parent link="L3"/>
    <child  link="L4"/>
    <limit effort="30" velocity="1.0"/>
    <axis xyz="0 0 1"/>
  </joint>


  <link name="L4">
    <inertial>
      <origin xyz="-0.01260 -0.00010 0.05450"/>
      <mass value="4.00000"/>
      <inertia ixx="0.00100" iyy="0.00133" izz="0.00118" ixy="0.00000" ixz="-0.00000" iyz="0.00006"/>
    </inertial>
    <visual>
      <origin xyz="0.0 0.0 0.0" rpy="0.0 0.0 0.0"/>
      <geometry>
	      <mesh filename="package://robot_properties_iiwa/meshes/iiwa14_link4.stl" scale="0.001 0.001 0.001" />
      </geometry>
    </visual>
  </link>


  <joint name="A5" type="revolute">
    <origin xyz="0.00000 0.18450 0.00000" rpy="-1.5707963705062866 0.0 -0.0"/>
    <parent link="L4"/>
    <child  link="L5"/>
    <limit effort="30" velocity="1.0"/>
    <axis xyz="0 0 1"/>
  </joint>


  <link name="L5">
    <inertial>
      <origin xyz="-0.01260 -0.00010 0.05450"/>
      <mass value="3.00000"/>
      <inertia ixx="0.00100" iyy="0.00133" izz="0.00118" ixy="0.00000" ixz="-0.00000" iyz="0.00001"/>
    </inertial>
    <visual>
      <origin xyz="0.0 0.0 0.0" rpy="0.0 0.0 0.0"/>
      <geometry>
	      <mesh filename="package://robot_properties_iiwa/meshes/iiwa14_link5.stl" scale="0.001 0.001 0.001" />
      </geometry>
    </visual>
  </link>


  <joint name="A6" type="revolute">
    <origin xyz="0.00000 -0.06070 0.21550" rpy="2.3561944901923457 -1.5707962635746238 2.3561944901923457"/>
    <parent link="L5"/>
    <child  link="L6"/>
    <limit effort="30" velocity="1.0"/>
    <axis xyz="0 0 1"/>
  </joint>
  

  <link name="L6">
    <inertial>
      <origin xyz="-0.05000 0.00400 0.12700"/>
      <mass value="2.00000"/>
      <inertia ixx="0.00354" iyy="0.00416" izz="0.00104" ixy="0.00000" ixz="-0.00000" iyz="-0.00000"/>
    </inertial>
    <visual>
      <origin xyz="0.0 0.0 0.0" rpy="0.0 0.0 0.0"/>
      <geometry>
	      <mesh filename="package://robot_properties_iiwa/meshes/iiwa14_link6.stl" scale="0.001 0.001 0.001" />
      </geometry>
    </visual>
  </link>

  
  <joint name="A7" type="revolute">
    <origin xyz="0.08100 0.00000 0.06070" rpy="1.5707963267948948 -4.371139000186238E-8 1.5707963705062866"/>
    <parent link="L6"/>
    <child  link="L7"/>
    <limit effort="30" velocity="1.0"/>
    <axis xyz="0 0 1"/>
  </joint>


  <link name="L7">
    <inertial>
      <origin xyz="-0.05000 0.00400 0.12700"/>
      <mass value="1.00000"/>
      <inertia ixx="0.00354" iyy="0.00416" izz="0.00104" ixy="0.00000" ixz="0.00000" iyz="-0.00000"/>
    </inertial>

    <visual>      
      <origin xyz="0.0 0.0 0.0" rpy="0.0 0.0 0.0"/>
      <geometry>
	      <mesh filename="package://robot_properties_iiwa/meshes/iiwa14_link7.stl" scale="0.001 0.001 0.001" />
      </geometry>
    </visual>
  </link>


  <joint name="END" type="fixed">
    <parent link="L7"/>
    <child link="contact"/>
    <!-- Joint placement -->
    <origin rpy="0 0 0" xyz="0 0.0 0.04"/>
    <!-- Limits (usefull?) -->
    <limit effort="1000" lower="-10" upper="10" velocity="1000"/>
    <!-- pybullet simulation parameters -->
    <dynamics damping="0.0" friction="0.0"/>
  </joint>


  <link name="contact">
    <!-- Modeling the contact as a tennis ball. -->
    <inertial>
      <origin rpy="0 0 0" xyz="0 0 0.0"/>
      <mass value="0.057"/>
      <inertia ixx="0.0000354" ixy="0.0" ixz="0.0" iyy="0.0000354" iyz="0.0" izz="0.0000354"/>
    </inertial>

    <visual>
      <origin rpy="0 0 0" xyz="0 0 0"/>
      <geometry>
        <!-- Using unit sphere and rescale to 6.5 cm diameter of tennis ball. -->
        <!-- TODO(skleff): Figure out if the scaling is correct to give us a 6.5 cm sphere. -->
        <mesh filename="package://robot_properties_iiwa/meshes/sphere.obj" scale="0.065 0.065 0.065"/>/>
      </geometry>
      <material name="grey">
        <color rgba="0.8 0.8 0.8 1.0"/>
      </material>
    </visual>

    <collision>
      <origin rpy="0 0 0" xyz="0 0 0"/>
      <geometry>
        <mesh filename="package://robot_properties_iiwa/meshes/sphere.obj" scale="0.065 0.065 0.065"/>/>
      </geometry>
      <material name="grey">
        <color rgba="0.8 0.8 0.8 1.0"/>
      </material>
    </collision>

    <!-- Bullet specific paramters -->
    <contact>
      <lateral_friction value="1.0"/>
      <restitution value="0.5"/>
    </contact>
  </link>


</robot>
